[2022-03-15 17:15:17,063] {taskinstance.py:1032} INFO - Dependencies all met for <TaskInstance: imdb_name_basics.local_to_gcs_task scheduled__2022-03-14T00:00:00+00:00 [queued]>
[2022-03-15 17:15:17,575] {taskinstance.py:1032} INFO - Dependencies all met for <TaskInstance: imdb_name_basics.local_to_gcs_task scheduled__2022-03-14T00:00:00+00:00 [queued]>
[2022-03-15 17:15:17,588] {taskinstance.py:1238} INFO - 
--------------------------------------------------------------------------------
[2022-03-15 17:15:17,604] {taskinstance.py:1239} INFO - Starting attempt 1 of 2
[2022-03-15 17:15:17,610] {taskinstance.py:1240} INFO - 
--------------------------------------------------------------------------------
[2022-03-15 17:15:18,010] {taskinstance.py:1259} INFO - Executing <Task(PythonOperator): local_to_gcs_task> on 2022-03-14 00:00:00+00:00
[2022-03-15 17:15:18,210] {standard_task_runner.py:52} INFO - Started process 276 to run task
[2022-03-15 17:15:18,350] {standard_task_runner.py:76} INFO - Running: ['***', 'tasks', 'run', 'imdb_name_basics', 'local_to_gcs_task', 'scheduled__2022-03-14T00:00:00+00:00', '--job-id', '368', '--raw', '--subdir', 'DAGS_FOLDER/name_basics_dag.py', '--cfg-path', '/tmp/tmp9zvht8tp', '--error-file', '/tmp/tmp05ba1ufa']
[2022-03-15 17:15:18,381] {standard_task_runner.py:77} INFO - Job 368: Subtask local_to_gcs_task
[2022-03-15 17:15:19,480] {logging_mixin.py:109} INFO - Running <TaskInstance: imdb_name_basics.local_to_gcs_task scheduled__2022-03-14T00:00:00+00:00 [running]> on host d8c9f2003356
[2022-03-15 17:15:21,048] {taskinstance.py:1426} INFO - Exporting the following env vars:
AIRFLOW_CTX_DAG_OWNER=***
AIRFLOW_CTX_DAG_ID=imdb_name_basics
AIRFLOW_CTX_TASK_ID=local_to_gcs_task
AIRFLOW_CTX_EXECUTION_DATE=2022-03-14T00:00:00+00:00
AIRFLOW_CTX_DAG_RUN_ID=scheduled__2022-03-14T00:00:00+00:00
[2022-03-15 17:15:21,964] {taskinstance.py:1700} ERROR - Task failed with exception
Traceback (most recent call last):
  File "/home/airflow/.local/lib/python3.7/site-packages/airflow/models/taskinstance.py", line 1329, in _run_raw_task
    self._execute_task_with_callbacks(context)
  File "/home/airflow/.local/lib/python3.7/site-packages/airflow/models/taskinstance.py", line 1455, in _execute_task_with_callbacks
    result = self._execute_task(context, self.task)
  File "/home/airflow/.local/lib/python3.7/site-packages/airflow/models/taskinstance.py", line 1511, in _execute_task
    result = execute_callable(context=context)
  File "/home/airflow/.local/lib/python3.7/site-packages/airflow/operators/python.py", line 174, in execute
    return_value = self.execute_callable()
  File "/home/airflow/.local/lib/python3.7/site-packages/airflow/operators/python.py", line 185, in execute_callable
    return self.python_callable(*self.op_args, **self.op_kwargs)
  File "/opt/airflow/dags/scripts/upload_to_gcs.py", line 21, in upload_to_gcs
    blob.upload_from_filename(local_file)
  File "/home/airflow/.local/lib/python3.7/site-packages/google/cloud/storage/blob.py", line 2720, in upload_from_filename
    with open(filename, "rb") as file_obj:
FileNotFoundError: [Errno 2] No such file or directory: '/opt/airflow/name.basics.tsv /opt/airflow/name.basics.parquet'
[2022-03-15 17:15:22,389] {taskinstance.py:1277} INFO - Marking task as UP_FOR_RETRY. dag_id=imdb_name_basics, task_id=local_to_gcs_task, execution_date=20220314T000000, start_date=20220315T171517, end_date=20220315T171522
[2022-03-15 17:15:23,098] {standard_task_runner.py:92} ERROR - Failed to execute job 368 for task local_to_gcs_task
Traceback (most recent call last):
  File "/home/airflow/.local/lib/python3.7/site-packages/airflow/task/task_runner/standard_task_runner.py", line 85, in _start_by_fork
    args.func(args, dag=self.dag)
  File "/home/airflow/.local/lib/python3.7/site-packages/airflow/cli/cli_parser.py", line 48, in command
    return func(*args, **kwargs)
  File "/home/airflow/.local/lib/python3.7/site-packages/airflow/utils/cli.py", line 92, in wrapper
    return f(*args, **kwargs)
  File "/home/airflow/.local/lib/python3.7/site-packages/airflow/cli/commands/task_command.py", line 298, in task_run
    _run_task_by_selected_method(args, dag, ti)
  File "/home/airflow/.local/lib/python3.7/site-packages/airflow/cli/commands/task_command.py", line 107, in _run_task_by_selected_method
    _run_raw_task(args, ti)
  File "/home/airflow/.local/lib/python3.7/site-packages/airflow/cli/commands/task_command.py", line 184, in _run_raw_task
    error_file=args.error_file,
  File "/home/airflow/.local/lib/python3.7/site-packages/airflow/utils/session.py", line 70, in wrapper
    return func(*args, session=session, **kwargs)
  File "/home/airflow/.local/lib/python3.7/site-packages/airflow/models/taskinstance.py", line 1329, in _run_raw_task
    self._execute_task_with_callbacks(context)
  File "/home/airflow/.local/lib/python3.7/site-packages/airflow/models/taskinstance.py", line 1455, in _execute_task_with_callbacks
    result = self._execute_task(context, self.task)
  File "/home/airflow/.local/lib/python3.7/site-packages/airflow/models/taskinstance.py", line 1511, in _execute_task
    result = execute_callable(context=context)
  File "/home/airflow/.local/lib/python3.7/site-packages/airflow/operators/python.py", line 174, in execute
    return_value = self.execute_callable()
  File "/home/airflow/.local/lib/python3.7/site-packages/airflow/operators/python.py", line 185, in execute_callable
    return self.python_callable(*self.op_args, **self.op_kwargs)
  File "/opt/airflow/dags/scripts/upload_to_gcs.py", line 21, in upload_to_gcs
    blob.upload_from_filename(local_file)
  File "/home/airflow/.local/lib/python3.7/site-packages/google/cloud/storage/blob.py", line 2720, in upload_from_filename
    with open(filename, "rb") as file_obj:
FileNotFoundError: [Errno 2] No such file or directory: '/opt/airflow/name.basics.tsv /opt/airflow/name.basics.parquet'
[2022-03-15 17:15:23,821] {local_task_job.py:154} INFO - Task exited with return code 1
[2022-03-15 17:15:24,561] {local_task_job.py:264} INFO - 0 downstream tasks scheduled from follow-on schedule check
